pyserver runing Sun Aug  6 15:25:00 2017
pyserver runing Sun Aug  6 15:27:35 2017
pyserver runing Sun Aug  6 15:28:19 2017
pyserver runing Sun Aug  6 15:31:09 2017
pyserver runing Sun Aug  6 15:32:23 2017
pyserver runing Sun Aug  6 15:33:06 2017
pyserver runing Sun Aug  6 15:37:33 2017
pyserver runing Sun Aug  6 15:39:46 2017
pyserver runing Sun Aug  6 15:46:26 2017
pyserver runing Sun Aug  6 15:46:58 2017
pyserver runing Sun Aug  6 15:47:34 2017
pyserver runing Sun Aug  6 16:02:53 2017
pyserver runing Sun Aug  6 16:05:51 2017
pyserver runing Sun Aug  6 16:06:02 2017
pyserver runing Sun Aug  6 16:33:11 2017
pyserver runing Sun Aug  6 16:34:31 2017
pyserver runing Sun Aug  6 16:34:46 2017
pyserver runing Sun Aug  6 16:35:29 2017
pyserver runing Sun Aug  6 16:35:44 2017
pyserver runing Sun Aug  6 16:36:03 2017
pyserver runing Sun Aug  6 16:37:58 2017
pyserver runing Sun Aug  6 16:38:23 2017
pyserver runing Sun Aug  6 16:39:07 2017
pyserver runing Sun Aug  6 17:06:07 2017
pyserver runing Sun Aug  6 17:36:10 2017
pyserver runing Sun Aug  6 18:06:15 2017
pyserver runing Sun Aug  6 18:36:17 2017
pyserver runing Sun Aug  6 19:06:18 2017
pyserver runing Sun Aug  6 19:36:23 2017
pyserver runing Sun Aug  6 21:11:53 2017
pyserver runing Sun Aug  6 21:41:57 2017
pyserver runing Sun Aug  6 22:12:00 2017
pyserver runing Sun Aug  6 22:42:01 2017
pyserver runing Mon Aug  7 11:48:05 2017
Traceback (most recent call last):
  File "/usr/lib/python3/dist-packages/urllib3/connection.py", line 137, in _new_conn
    (self.host, self.port), self.timeout, **extra_kw)
  File "/usr/lib/python3/dist-packages/urllib3/util/connection.py", line 67, in create_connection
    for res in socket.getaddrinfo(host, port, 0, socket.SOCK_STREAM):
  File "/usr/lib/python3.5/socket.py", line 732, in getaddrinfo
    for res in _socket.getaddrinfo(host, port, family, type, proto, flags):
socket.gaierror: [Errno -3] Temporary failure in name resolution

During handling of the above exception, another exception occurred:

Traceback (most recent call last):
  File "/usr/lib/python3/dist-packages/urllib3/connectionpool.py", line 560, in urlopen
    body=body, headers=headers)
  File "/usr/lib/python3/dist-packages/urllib3/connectionpool.py", line 354, in _make_request
    conn.request(method, url, **httplib_request_kw)
  File "/usr/lib/python3.5/http/client.py", line 1106, in request
    self._send_request(method, url, body, headers)
  File "/usr/lib/python3.5/http/client.py", line 1151, in _send_request
    self.endheaders(body)
  File "/usr/lib/python3.5/http/client.py", line 1102, in endheaders
    self._send_output(message_body)
  File "/usr/lib/python3.5/http/client.py", line 934, in _send_output
    self.send(msg)
  File "/usr/lib/python3.5/http/client.py", line 877, in send
    self.connect()
  File "/usr/lib/python3/dist-packages/urllib3/connection.py", line 162, in connect
    conn = self._new_conn()
  File "/usr/lib/python3/dist-packages/urllib3/connection.py", line 146, in _new_conn
    self, "Failed to establish a new connection: %s" % e)
requests.packages.urllib3.exceptions.NewConnectionError: <requests.packages.urllib3.connection.HTTPConnection object at 0x7fb7102da668>: Failed to establish a new connection: [Errno -3] Temporary failure in name resolution

During handling of the above exception, another exception occurred:

Traceback (most recent call last):
  File "/usr/lib/python3/dist-packages/requests/adapters.py", line 376, in send
    timeout=timeout
  File "/usr/lib/python3/dist-packages/urllib3/connectionpool.py", line 610, in urlopen
    _stacktrace=sys.exc_info()[2])
  File "/usr/lib/python3/dist-packages/urllib3/util/retry.py", line 273, in increment
    raise MaxRetryError(_pool, url, error or ResponseError(cause))
requests.packages.urllib3.exceptions.MaxRetryError: HTTPConnectionPool(host='www.dm5.com', port=80): Max retries exceeded with url: /manhua-zhengzongdefuchou/ (Caused by NewConnectionError('<requests.packages.urllib3.connection.HTTPConnection object at 0x7fb7102da668>: Failed to establish a new connection: [Errno -3] Temporary failure in name resolution',))

During handling of the above exception, another exception occurred:

Traceback (most recent call last):
  File "/home/fire/MyFile/manka/zzj/zzj.py", line 73, in <module>
    getNewest()
  File "/home/fire/MyFile/manka/zzj/zzj.py", line 22, in getNewest
    raise e
  File "/home/fire/MyFile/manka/zzj/zzj.py", line 18, in getNewest
    r = requests.get(url)
  File "/usr/lib/python3/dist-packages/requests/api.py", line 67, in get
    return request('get', url, params=params, **kwargs)
  File "/usr/lib/python3/dist-packages/requests/api.py", line 53, in request
    return session.request(method=method, url=url, **kwargs)
  File "/usr/lib/python3/dist-packages/requests/sessions.py", line 468, in request
    resp = self.send(prep, **send_kwargs)
  File "/usr/lib/python3/dist-packages/requests/sessions.py", line 576, in send
    r = adapter.send(request, **kwargs)
  File "/usr/lib/python3/dist-packages/requests/adapters.py", line 437, in send
    raise ConnectionError(e, request=request)
requests.exceptions.ConnectionError: HTTPConnectionPool(host='www.dm5.com', port=80): Max retries exceeded with url: /manhua-zhengzongdefuchou/ (Caused by NewConnectionError('<requests.packages.urllib3.connection.HTTPConnection object at 0x7fb7102da668>: Failed to establish a new connection: [Errno -3] Temporary failure in name resolution',))
pyserver runing Mon Aug  7 11:48:06 2017
pyserver runing Mon Aug  7 12:18:08 2017
pyserver runing Mon Aug  7 12:48:10 2017
pyserver runing Mon Aug  7 13:18:18 2017
pyserver runing Mon Aug  7 13:48:19 2017
pyserver runing Mon Aug  7 14:18:20 2017
pyserver runing Mon Aug  7 14:48:22 2017
zzj checking runing Mon Aug  7 14:59:33 2017
zzj checking runing Mon Aug  7 15:29:38 2017
zzj checking runing Mon Aug  7 15:59:42 2017
zzj checking runing Mon Aug  7 16:29:42 2017
zzj checking runing Mon Aug  7 16:59:45 2017
zzj checking runing Mon Aug  7 17:29:50 2017
zzj checking runing Mon Aug  7 17:59:51 2017
